Workbook

Sheet TOC
B2: Principal Component Analysis (PCA) for Multiple Linear Regression (MLR)
B3: Comprehensive Q&A Notes • Illustrations • Hyperlinked Table of Contents
B5: 📑 Table of Contents | C5: Topic | D5: What you'll learn
B6: Section 1 | C6: =HYPERLINK("#'1. MLR Recap'!A1","1. MLR Recap") -> 1. MLR Recap | D6: Quick refresher on Multiple Linear Regression — equation, assumptions, OLS.
B7: Section 2 | C7: =HYPERLINK("#'2. The Problem'!A1","2. The Problem with MLR") -> 2. The Problem with MLR | D7: Multicollinearity — why correlated predictors break MLR, and how to spot it (VIF).
B8: Section 3 | C8: =HYPERLINK("#'3. PCA Intuition'!A1","3. PCA — The Intuition") -> 3. PCA — The Intuition | D8: What PCA is, in plain English. Rotating axes to capture maximum variance.
B9: Section 4 | C9: =HYPERLINK("#'4. PCA Math'!A1","4. The Math Behind PCA") -> 4. The Math Behind PCA | D9: Covariance matrix, eigenvalues, eigenvectors, and explained variance.
B10: Section 5 | C10: =HYPERLINK("#'5. PCA Steps'!A1","5. PCA Step-by-Step") -> 5. PCA Step-by-Step | D10: The full PCA recipe — standardize, decompose, project, choose k components.
B11: Section 6 | C11: =HYPERLINK("#'6. PCR (PCA+MLR)'!A1","6. Principal Component Regression") -> 6. Principal Component Regression | D11: Combining PCA with MLR — how PCR works and when to use it.
B12: Section 7 | C12: =HYPERLINK("#'7. Illustration'!A1","7. Worked Illustration") -> 7. Worked Illustration | D12: Numerical example: 2-variable dataset with charts showing PC1 & PC2 rotation.
B13: Section 8 | C13: =HYPERLINK("#'8. Pros & Cons'!A1","8. Pros, Cons & Pitfalls") -> 8. Pros, Cons & Pitfalls | D13: When PCR shines, when it hurts, and common mistakes to avoid.
B14: Section 9 | C14: =HYPERLINK("#'9. Glossary & FAQ'!A1","9. Glossary & FAQ") -> 9. Glossary & FAQ | D14: Definitions of key terms + frequently asked exam-style questions.
B15: Section 10 | C15: =HYPERLINK("#'10. Case Study'!A1","10. Case Study: House Price Prediction") -> 10. Case Study: House Price Prediction | D15: End-to-end PCR example: 12 houses, 5 correlated features, full workflow with verdict.
B16: 💡 How to use this workbook
B17: • Click any colored link to jump to that section. • Each section uses a Q&A format. • Section 7 has live charts you can interact with. • Each section has a ⬅ Back to TOC link.

Sheet 1. MLR Recap
B2: Section 1 — Multiple Linear Regression: A Quick Recap
B3: =HYPERLINK("#TOC!A1","⬅ Back to Table of Contents") -> ⬅ Back to Table of Contents
B5: Q1. What is Multiple Linear Regression (MLR)?
B6: MLR is a statistical method that models the relationship between ONE dependent variable (Y) and TWO OR MORE independent variables (X₁, X₂, ..., Xₚ). It extends Simple Linear Regression (which has only one X) to multiple predictors.
B8: Q2. What is the MLR equation?
B9: Y = β₀ + β₁X₁ + β₂X₂ + ... + βₚXₚ + ε
B10: Where: Y = response variable • β₀ = intercept • βᵢ = coefficient (effect of Xᵢ on Y, holding others constant) • ε = error term
B12: Q3. How are the coefficients (β) estimated?
B13: Using Ordinary Least Squares (OLS) — we choose β values that MINIMIZE the sum of squared errors: SSE = Σ(Yᵢ − Ŷᵢ)². The closed-form solution is: β̂ = (XᵀX)⁻¹ XᵀY
B15: Q4. What are the key assumptions of MLR?
B16: 1. Linearity — relationship between X and Y is linear.
B17: 2. Independence — observations are independent of each other.
B18: 3. Homoscedasticity — constant variance of errors across all X values.
B19: 4. Normality of errors — residuals are normally distributed.
... B28: 💡 Key takeaway: MLR works beautifully WHEN its assumptions hold. The trouble starts when predictors are correlated → that's where PCA enters.

Sheet 2. The Problem
B2: Section 2 — The Problem with MLR: Multicollinearity
B3: =HYPERLINK("#TOC!A1","⬅ Back to Table of Contents") -> ⬅ Back to Table of Contents
B5: Q1. What is multicollinearity?
B6: Multicollinearity = when two or more predictor variables (X's) in your MLR are HIGHLY CORRELATED with each other. Example: predicting house price using both 'area in sqft' and 'number of rooms' — these move together!
B8: Q2. Why is multicollinearity a problem?
B9: When predictors carry overlapping information, OLS cannot decide which one deserves credit. Consequences:
B10: • Coefficient estimates (β) become UNSTABLE — small data changes → huge coefficient swings.
B11: • Standard errors INFLATE — t-values shrink, predictors look insignificant even if they matter.
B12: • Signs of coefficients may flip (positive becomes negative) — makes no business sense.
B13: • The (XᵀX) matrix becomes near-singular → (XᵀX)⁻¹ explodes → inverse computation fails.
B14: • Overall R² may stay high, but individual predictor inference is unreliable.
B16: Q3. How do we detect multicollinearity?
B17: 1. Correlation matrix — if |r| > 0.8 between predictors, suspect multicollinearity.
B18: 2. Variance Inflation Factor (VIF) — VIFᵢ = 1 / (1 − Rᵢ²) where Rᵢ² is from regressing Xᵢ on all other X's.
... B29: 💡 Mini example: If X₁ = height in inches and X₂ = height in cm, they're perfectly correlated (r=1). MLR cannot separate their effects on Y. PCA would merge them into ONE component.

Sheet 3. PCA Intuition
B2: Section 3 — Principal Component Analysis: The Intuition
B3: =HYPERLINK("#TOC!A1","⬅ Back to Table of Contents") -> ⬅ Back to Table of Contents
B5: Q1. What is PCA in one sentence?
B6: PCA is a technique that TRANSFORMS your original correlated variables into a smaller set of NEW UNCORRELATED variables (called principal components) that retain most of the information.
B8: Q2. What's the everyday analogy?
B9: Imagine photographing a 3D object — the best 2D photo is the one taken from the angle showing the MOST detail (the most variance). PCA finds those 'best angles' (axes) mathematically.
B10: Another: A swarm of points stretched diagonally on a graph. Rotating your axes so the longest spread is on one axis = PC1. PC1 alone tells you most of the story.
B12: Q3. What is a 'principal component'?
B13: A principal component is a LINEAR COMBINATION of the original variables:
B14: PC1 = w₁₁·X₁ + w₁₂·X₂ + ... + w₁ₚ·Xₚ
B15: The weights (w) are chosen so PC1 captures MAXIMUM variance. PC2 captures the next-most variance AND is uncorrelated with PC1. And so on.
B17: Q4. What three magic properties do PCs have?
B18: 1. 🔗 ORTHOGONAL — PCs are perpendicular to each other → ZERO correlation among them.
B19: 2. 📊 ORDERED — PC1 explains the most variance, PC2 the next, etc.
... B34: 💡 Takeaway: PCA = ROTATION of axes to align with the directions of greatest data spread. It DOES NOT delete information — it REORGANISES it.

Sheet 4. PCA Math
B2: Section 4 — The Math Behind PCA
B3: =HYPERLINK("#TOC!A1","⬅ Back to Table of Contents") -> ⬅ Back to Table of Contents
B5: Q1. What is the covariance matrix and why do we care?
B6: Covariance matrix Σ (size p×p) holds the covariance between every pair of variables. Its diagonal = variances, off-diagonal = pairwise covariances. PCA's job is to find directions that DIAGONALISE this matrix.
B7: Cov(X) = (1/(n-1))·(X−X̄)ᵀ(X−X̄)
B9: Q2. What are eigenvalues and eigenvectors?
B10: For a square matrix A, a vector v and scalar λ satisfying A·v = λ·v are called an EIGENVECTOR and EIGENVALUE.
B11: • Eigenvector = direction that doesn't change when A acts on it (only stretched).
B12: • Eigenvalue = stretching factor (how much variance is in that direction).
B14: Q3. How do PCs come from eigen-decomposition?
B15: Decompose the covariance matrix: Σ = V·Λ·Vᵀ
B16: • V = columns are eigenvectors = directions of PCs (these are the 'loadings').
B17: • Λ = diagonal matrix of eigenvalues = variance captured by each PC.
B18: Sort eigenvalues descending. The largest λ → PC1, next → PC2, etc.
... B31: 💡 Mental model: Cov matrix → eigen-decomposition → sorted eigenvectors = new axes; eigenvalues tell you how much variance lives on each new axis.

Sheet 5. PCA Steps
B2: Section 5 — PCA Step-by-Step Recipe
B3: =HYPERLINK("#TOC!A1","⬅ Back to Table of Contents") -> ⬅ Back to Table of Contents
B5: The 7-step PCA workflow
B7: STEP 1 — Organise the data
B8: Arrange data as a matrix X of size n×p (n rows = observations, p columns = predictor variables). DO NOT include the response variable Y in PCA.
B10: STEP 2 — Centre (and Standardise) the data
B11: Subtract each column's mean (centre). If variables are on different scales (e.g., kg vs $), also divide by std dev (standardise) so PCA isn't dominated by large-scale variables. This step is CRITICAL.
B12: Z = (X − μ) / σ
B14: STEP 3 — Compute the covariance (or correlation) matrix
B15: If standardised → use correlation matrix. Size = p×p.
B17: STEP 4 — Eigen-decompose the matrix
B18: Get p eigenvalues (λ₁ ≥ λ₂ ≥ ... ≥ λₚ) and corresponding eigenvectors.
B20: STEP 5 — Choose number of components (k)
B21: Common rules:
... B33: ⚠️ Common mistake: forgetting to standardise. A 'sales (in $)' variable will dwarf 'unit count' and bias PC1 simply because of scale.

Sheet 6. PCR (PCA+MLR)
B2: Section 6 — Principal Component Regression (PCR)
B3: =HYPERLINK("#TOC!A1","⬅ Back to Table of Contents") -> ⬅ Back to Table of Contents
B5: Q1. What is PCR?
B6: Principal Component Regression = PCA followed by MLR. Instead of regressing Y on X₁...Xₚ, we regress Y on the principal components (PC scores) Z₁...Z_k.
B8: Q2. What is the PCR equation?
B9: Y = α₀ + α₁Z₁ + α₂Z₂ + ... + α_k Z_k + ε
B10: Where Z₁...Z_k are PC scores. Since they're uncorrelated, each α is independently and stably estimated.
B12: Q3. How do I get back to coefficients on the ORIGINAL variables?
B13: Use the loadings (V_k) to translate: β̂ = V_k · α̂
B14: If you standardised X, you must also rescale β back to original units using the column std devs.
B16: Q4. Full PCR workflow (cheat sheet)
B17: 1. Standardise X. 2. Run PCA → obtain scores Z and loadings V. 3. Decide k (variance cutoff / CV).
B18: 4. Fit OLS: Y on Z₁...Z_k. 5. (Optional) Map back to original β. 6. Predict Y for new x by applying the same transformations.
B20: Q5. Why does PCR cure multicollinearity?
... B28: ⚠️ Caveat: PC1 captures most variance in X — but that doesn't guarantee it best predicts Y. Sometimes a low-variance PC carries the Y signal. Always validate.

Sheet 7. Illustration
B2: Section 7 — Worked Illustration: PCA on a 2-variable Dataset
B3: =HYPERLINK("#TOC!A1","⬅ Back to Table of Contents") -> ⬅ Back to Table of Contents
B5: Scenario: Two predictors X₁ and X₂ are highly correlated (e.g., height in cm and weight in kg).
B6: We'll compute means, centred values, covariance, eigen-decomposition, and PC scores — all using live formulas.
B8: 🔹 Raw Data | H8: 🔹 Covariance Matrix Σ (2×2) | L8: 🔹 Eigenvectors (loadings)
B9: Obs | C9: X₁ | D9: X₂ | E9: X₁−μ₁ (centred) | F9: X₂−μ₂ (centred) | I9: X₁ | J9: X₂ | L9: Direction | M9: v(X₁) | N9: v(X₂)
B10: 1 | C10: 2.5 | D10: 2.4 | E10: =C10-$C$21 -> 0.69 | F10: =D10-$D$21 -> 0.49 | H10: X₁ | I10: =_xlfn.VAR.S(C10:C19) -> 0.61655556 | J10: =_xlfn.COVARIANCE.S(C10:C19,D10:D19) -> 0.61544444 | L10: PC1 | M10: =J10/SQRT(J10^2+(I17-I10)^2) -> 0.6778734 | N10: =(I17-I10)/SQRT(J10^2+(I17-I10)^2) -> 0.73517866
B11: 2 | C11: 0.5 | D11: 0.7 | E11: =C11-$C$21 -> -1.31 | F11: =D11-$D$21 -> -1.21 | H11: X₂ | I11: =_xlfn.COVARIANCE.S(C10:C19,D10:D19) -> 0.61544444 | J11: =_xlfn.VAR.S(D10:D19) -> 0.71655556 | L11: PC2 | M11: =-N10 -> -0.73517866 | N11: =M10 -> 0.6778734
B12: 3 | C12: 2.2 | D12: 2.9 | E12: =C12-$C$21 -> 0.39 | F12: =D12-$D$21 -> 0.99
B13: 4 | C13: 1.9 | D13: 2.2 | E13: =C13-$C$21 -> 0.09 | F13: =D13-$D$21 -> 0.29 | H13: 🔹 Eigenvalues (closed-form for 2×2) | L13: → PC1 ≈ 0.677·X₁ + 0.735·X₂ (both positive → 'overall size' axis)
B14: 5 | C14: 3.1 | D14: 3 | E14: =C14-$C$21 -> 1.29 | F14: =D14-$D$21 -> 1.09 | H14: Trace (a+d) | I14: =I10+J11 -> 1.3331111
B15: 6 | C15: 2.3 | D15: 2.7 | E15: =C15-$C$21 -> 0.49 | F15: =D15-$D$21 -> 0.79 | H15: Det (ad−bc) | I15: =I10*J11-J10*I11 -> 0.063024444
B16: 7 | C16: 2 | D16: 1.6 | E16: =C16-$C$21 -> 0.19 | F16: =D16-$D$21 -> -0.31 | H16: Discriminant | I16: =SQRT(I14^2-4*I15) -> 1.2349443
B17: 8 | C17: 1 | D17: 1.1 | E17: =C17-$C$21 -> -0.81 | F17: =D17-$D$21 -> -0.81 | H17: λ₁ (largest) | I17: =(I14+I16)/2 -> 1.2840277
B18: 9 | C18: 1.5 | D18: 1.6 | E18: =C18-$C$21 -> -0.31 | F18: =D18-$D$21 -> -0.31 | H18: λ₂ | I18: =(I14-I16)/2 -> 0.049083399
B19: 10 | C19: 1.1 | D19: 0.9 | E19: =C19-$C$21 -> -0.71 | F19: =D19-$D$21 -> -1.01
H20: 🔹 Explained Variance
B21: Mean (μ) | C21: =AVERAGE(C10:C19) -> 1.81 | D21: =AVERAGE(D10:D19) -> 1.91 | H21: PC1 % | I21: =I17/(I17+I18) -> 0.96318131
B22: Std Dev (σ) | C22: =_xlfn.STDEV.S(C10:C19) -> 0.78521052 | D22: =_xlfn.STDEV.S(D10:D19) -> 0.84649605 | H22: PC2 % | I22: =I18/(I17+I18) -> 0.036818686
B23: Correlation r(X₁,X₂) | C23: =CORREL(C10:C19,D10:D19) -> 0.92592927 | D23: ← high → multicollinear!
B25: 🔹 PC Scores (Projection of centred data onto eigenvectors)
B26: Obs | C26: PC1 Score | D26: PC2 Score
B27: =B10 -> 1 | C27: =E10*$M$10+F10*$N$10 -> 0.82797019 | D27: =E10*$M$11+F10*$N$11 -> -0.17511531
B28: =B11 -> 2 | C28: =E11*$M$10+F11*$N$10 -> -1.7775803 | D28: =E11*$M$11+F11*$N$11 -> 0.14285723
B29: =B12 -> 3 | C29: =E12*$M$10+F12*$N$10 -> 0.99219749 | D29: =E12*$M$11+F12*$N$11 -> 0.38437499
B30: =B13 -> 4 | C30: =E13*$M$10+F13*$N$10 -> 0.27421042 | D30: =E13*$M$11+F13*$N$11 -> 0.13041721
B31: =B14 -> 5 | C31: =E14*$M$10+F14*$N$10 -> 1.6758014 | D31: =E14*$M$11+F14*$N$11 -> -0.20949846
B32: =B15 -> 6 | C32: =E15*$M$10+F15*$N$10 -> 0.9129491 | D32: =E15*$M$11+F15*$N$11 -> 0.17528244
B33: =B16 -> 7 | C33: =E16*$M$10+F16*$N$10 -> -0.099109437 | D33: =E16*$M$11+F16*$N$11 -> -0.3498247
B34: =B17 -> 8 | C34: =E17*$M$10+F17*$N$10 -> -1.1445722 | D34: =E17*$M$11+F17*$N$11 -> 0.046417258 | P34: PC | Q34: Explained Variance %
B35: =B18 -> 9 | C35: =E18*$M$10+F18*$N$10 -> -0.43804614 | D35: =E18*$M$11+F18*$N$11 -> 0.01776463 | P35: PC1 | Q35: =I21 -> 0.96318131
B36: =B19 -> 10 | C36: =E19*$M$10+F19*$N$10 -> -1.2238206 | D36: =E19*$M$11+F19*$N$11 -> -0.16267529 | P36: PC2 | Q36: =I22 -> 0.036818686
B38: ✅ Sanity check: correlation between PC1 and PC2 scores = | D38: =CORREL(C27:C36,D27:D36) -> -4.0415608e-15 | E38: ← essentially zero → PCs are uncorrelated!
B40: 📊 What the charts to the right show
B41: Chart 1 — ORIGINAL data with X₁ vs X₂: notice the diagonal stretch (correlation ~0.93).
B42: Chart 2 — TRANSFORMED data (PC1 vs PC2 scores): the cloud is now horizontally spread along PC1 with almost no spread on PC2 → multicollinearity is gone.
B43: Chart 3 — Explained variance: PC1 alone captures ~96% of the variance. We could keep ONLY PC1 in MLR with minimal information loss.
B45: 🎓 Lesson: With one PC instead of two correlated X's, MLR becomes simpler, stabler, and just as informative.

Sheet 8. Pros & Cons
B2: Section 8 — Pros, Cons & Pitfalls of PCR
B3: =HYPERLINK("#TOC!A1","⬅ Back to Table of Contents") -> ⬅ Back to Table of Contents
B5: ✅ Advantages | C5: ❌ Disadvantages / Pitfalls
B6: Removes multicollinearity completely — PCs are orthogonal. | C6: PCs are abstract — they are mathematical combinations, harder to interpret than original variables.
B7: Reduces dimensionality — fewer predictors → simpler model, less overfitting. | C7: Unsupervised — PCA ignores Y; high-variance PCs may not predict Y well.
B8: Numerical stability — (ZᵀZ) is diagonal, easy to invert. | C8: Sensitive to scaling — forgetting to standardise gives misleading components.
B9: Noise filtering — dropping low-variance PCs often removes noise. | C9: Assumes linearity — PCA only captures linear structure in the data.
B10: Visualisation — first 2–3 PCs let you plot high-dimensional data. | C10: Sensitive to outliers — a single extreme point can dominate PC directions.
B11: Works on any number of predictors, including p > n cases (with regularised PCA). | C11: Choosing k (number of PCs) involves judgement — different rules give different answers.
B14: ⚠️ Common Pitfalls (memorise these!)
B15: 1. ❌ Forgetting to standardise when variables have different scales → largest-scale variable hijacks PC1.
B16: 2. ❌ Including Y in the PCA — PCA is done on X only. Y is regressed on PC scores afterwards.
B17: 3. ❌ Always keeping just PC1 — sometimes a 'small' PC carries critical predictive power for Y.
B18: 4. ❌ Interpreting PC coefficients as causal effects — they're directions, not drivers.
B19: 5. ❌ Applying PCA training-set means/std to NEW data — you must reuse the same μ, σ, V from training.
B21: 🎯 When to use PCR
B22: • Many predictors, several highly correlated. • You suspect noise dominates the smaller dimensions. • Sample size n is small relative to p. • Prediction matters more than coefficient interpretation.

Sheet 9. Glossary & FAQ
B2: Section 9 — Glossary & Frequently Asked Questions
B3: =HYPERLINK("#TOC!A1","⬅ Back to Table of Contents") -> ⬅ Back to Table of Contents
B5: 📖 Glossary
B6: Term | C6: Meaning
B7: Multicollinearity | C7: High correlation among predictor variables in regression, causing unstable coefficients.
B8: Principal Component (PC) | C8: Linear combination of original variables; new uncorrelated axis.
B9: Loading | C9: Weight of an original variable in a PC (entry of the eigenvector).
B10: Score | C10: Value of a PC for a specific observation (projection onto eigenvector).
B11: Eigenvalue (λ) | C11: Variance captured by its corresponding eigenvector / PC.
B12: Eigenvector (v) | C12: Direction in feature space along which variance is computed; defines a PC.
B13: Explained Variance | C13: λᵢ / Σλ — fraction of total variance captured by PCᵢ.
B14: Scree Plot | C14: Bar/line plot of eigenvalues used to choose k (look for the elbow).
B15: Standardisation | C15: Transform each variable to mean 0, std 1 before PCA.
B16: VIF | C16: Variance Inflation Factor — measures how much multicollinearity inflates a coefficient's variance.
B17: PCR | C17: Principal Component Regression — MLR using PC scores as predictors.
... B19: SVD | C19: Singular Value Decomposition — stable numerical method to compute PCA.
B22: ❓ Frequently Asked Questions
B23: Q1. Should I always standardise before PCA?
B24: A. Almost always YES when variables are on different scales/units. If all variables are already on a comparable scale (e.g., all percentages), centring alone may suffice.
B25: Q2. How many PCs should I keep?
B26: A. Use cumulative explained variance (~80–95%), scree-plot elbow, Kaiser's rule (λ>1), or cross-validation. For PCR, CV with respect to prediction error is the most defensible.
B27: Q3. Can I interpret PCs in terms of original variables?
B28: A. Yes, by examining the loadings (eigenvector entries). Large absolute loadings indicate strong contribution. Often a PC represents a meaningful concept (e.g., 'overall size', 'shape contrast').
B29: Q4. Is PCR always better than plain MLR?
B30: A. No. If predictors are not multicollinear and easily interpretable, plain MLR is preferable. PCR shines under multicollinearity, high p, or when prediction trumps interpretation.
B31: Q5. PCR or Ridge?
B32: A. Ridge keeps all original variables (shrinks them); PCR drops low-variance components. Ridge usually performs equally well or better predictively, and keeps original-variable interpretability.
B33: Q6. Does PCA work for categorical variables?
... B36: A. Centre & scale x_new using TRAINING μ and σ → multiply by training V_k → plug PC scores into the fitted MLR. Never recompute PCA on the new point.

Sheet 10. Case Study
B2: Section 10 — Case Study: Predicting House Prices with PCR
B3: =HYPERLINK("#TOC!A1","⬅ Back to Table of Contents") -> ⬅ Back to Table of Contents
B5: 🏠 Business Problem
B6: A real-estate analyst wants to predict house price (Y) using 5 features: Size (sqft), Bedrooms, Age (years), Lot size (sqft), Garage spaces. Many of these features intuitively move together — bigger houses tend to have more bedrooms, larger lots, more garage space. Multicollinearity is likely!
B8: 🔹 Step 1 — Raw Data (n = 12 houses, p = 5 features)
B9: House | C9: Size (sqft) | D9: Bedrooms | E9: Age (yrs) | F9: Lot (sqft) | G9: Garage | H9: Price ($000)
B10: 1 | C10: 1500 | D10: 3 | E10: 20 | F10: 5000 | G10: 1 | H10: 245
B11: 2 | C11: 2200 | D11: 4 | E11: 5 | F11: 7500 | G11: 2 | H11: 380
B12: 3 | C12: 1800 | D12: 3 | E12: 15 | F12: 6000 | G12: 2 | H12: 295
B13: 4 | C13: 2500 | D13: 4 | E13: 8 | F13: 8200 | G13: 2 | H13: 425
B14: 5 | C14: 1200 | D14: 2 | E14: 35 | F14: 4200 | G14: 1 | H14: 180
B15: 6 | C15: 3000 | D15: 5 | E15: 3 | F15: 10000 | G15: 3 | H15: 540
B16: 7 | C16: 1700 | D16: 3 | E16: 25 | F16: 5500 | G16: 1 | H16: 265
B17: 8 | C17: 2800 | D17: 4 | E17: 10 | F17: 9000 | G17: 2 | H17: 475
B18: 9 | C18: 2000 | D18: 3 | E18: 18 | F18: 6500 | G18: 2 | H18: 320
B19: 10 | C19: 1400 | D19: 2 | E19: 30 | F19: 4800 | G19: 1 | H19: 210
B20: 11 | C20: 2600 | D20: 4 | E20: 7 | F20: 8500 | G20: 3 | H20: 455
B21: 12 | C21: 1900 | D21: 3 | E21: 22 | F21: 6200 | G21: 2 | H21: 305
B23: 🔹 Step 2 — Spot the Problem: Correlation Matrix between predictors | J23: Using Data Analysis Correlation Matrix
C24: Size | D24: Bedrooms | E24: Age | F24: Lot | G24: Garage | K24: Size (sqft) | L24: Bedrooms | M24: Age (yrs) | N24: Lot (sqft) | O24: Garage
B25: Size | C25: =CORREL($C$10:$C$21,C$10:C$21) -> 1 | D25: =CORREL($C$10:$C$21,D$10:D$21) -> 0.94233081 | E25: =CORREL($C$10:$C$21,E$10:E$21) -> -0.8963478 | F25: =CORREL($C$10:$C$21,F$10:F$21) -> 0.99725836 | G25: =CORREL($C$10:$C$21,G$10:G$21) -> 0.85753991 | J25: Size (sqft) | K25: 1 | M25: {=TRANSPOSE(K27:K29)} -> -0.8963478 | N25: 0.99725836 | O25: 0.85753991
B26: Bedrooms | C26: =CORREL($D$10:$D$21,C$10:C$21) -> 0.94233081 | D26: =CORREL($D$10:$D$21,D$10:D$21) -> 1 | E26: =CORREL($D$10:$D$21,E$10:E$21) -> -0.94625394 | F26: =CORREL($D$10:$D$21,F$10:F$21) -> 0.95054055 | G26: =CORREL($D$10:$D$21,G$10:G$21) -> 0.80860754 | J26: Bedrooms | K26: 0.94233081 | L26: 1 | M26: {=TRANSPOSE(L27:L29)} -> -0.94625394 | N26: 0.95054055 | O26: 0.80860754
B27: Age | C27: =CORREL($E$10:$E$21,C$10:C$21) -> -0.8963478 | D27: =CORREL($E$10:$E$21,D$10:D$21) -> -0.94625394 | E27: =CORREL($E$10:$E$21,E$10:E$21) -> 1 | F27: =CORREL($E$10:$E$21,F$10:F$21) -> -0.90677559 | G27: =CORREL($E$10:$E$21,G$10:G$21) -> -0.82531761 | J27: Age (yrs) | K27: -0.8963478 | L27: -0.94625394 | M27: 1 | N27: {=TRANSPOSE(M28:M29)} -> -0.90677559 | O27: -0.82531761
B28: Lot | C28: =CORREL($F$10:$F$21,C$10:C$21) -> 0.99725836 | D28: =CORREL($F$10:$F$21,D$10:D$21) -> 0.95054055 | E28: =CORREL($F$10:$F$21,E$10:E$21) -> -0.90677559 | F28: =CORREL($F$10:$F$21,F$10:F$21) -> 1 | G28: =CORREL($F$10:$F$21,G$10:G$21) -> 0.8655741 | J28: Lot (sqft) | K28: 0.99725836 | L28: 0.95054055 | M28: -0.90677559 | N28: 1 | O28: =N29 -> 0.8655741
B29: Garage | C29: =CORREL($G$10:$G$21,C$10:C$21) -> 0.85753991 | D29: =CORREL($G$10:$G$21,D$10:D$21) -> 0.80860754 | E29: =CORREL($G$10:$G$21,E$10:E$21) -> -0.82531761 | F29: =CORREL($G$10:$G$21,F$10:F$21) -> 0.8655741 | G29: =CORREL($G$10:$G$21,G$10:G$21) -> 1 | J29: Garage | K29: 0.85753991 | L29: 0.80860754 | M29: -0.82531761 | N29: 0.8655741 | O29: 1
B31: 🚨 Observation: |r| > 0.9 for many pairs (Size↔Lot, Size↔Age, Size↔Bedrooms). Classic multicollinearity — plain MLR coefficients will be unstable!
B33: 🔹 Step 3 — Plain MLR (for comparison) using LINEST
B34: LINEST returns coefficients in REVERSE order: β(Garage), β(Lot), β(Age), β(Bedrooms), β(Size), β₀
B35: Coefficient | C35: β(Size) | D35: β(Bedrooms) | E35: β(Age) | F35: β(Lot) | G35: β(Garage) | H35: Intercept
B36: Estimate | C36: =INDEX(LINEST(H10:H21,C10:G21),1,5) -> 0.067598421 | D36: =INDEX(LINEST(H10:H21,C10:G21),1,4) -> 18.039164 | E36: =INDEX(LINEST(H10:H21,C10:G21),1,3) -> 0.20868031 | F36: =INDEX(LINEST(H10:H21,C10:G21),1,2) -> 0.031019504 | G36: =INDEX(LINEST(H10:H21,C10:G21),1,1) -> 6.3201254 | H36: =INDEX(LINEST(H10:H21,C10:G21),1,6) -> -82.903066
B37: Std Error | C37: =INDEX(LINEST(H10:H21,C10:G21,TRUE,TRUE),2,5) -> 0.038616678 | D37: =INDEX(LINEST(H10:H21,C10:G21,TRUE,TRUE),2,4) -> 7.8270407 | E37: =INDEX(LINEST(H10:H21,C10:G21,TRUE,TRUE),2,3) -> 0.50112674 | F37: =INDEX(LINEST(H10:H21,C10:G21,TRUE,TRUE),2,2) -> 0.01341953 | G37: =INDEX(LINEST(H10:H21,C10:G21,TRUE,TRUE),2,1) -> 4.680659 | H37: =INDEX(LINEST(H10:H21,C10:G21,TRUE,TRUE),2,6) -> 27.07611
B38: R² of full MLR = | C38: =INDEX(LINEST(H10:H21,C10:G21,TRUE,TRUE),3,1) -> 0.99885363 | D38: (high R² hides the instability!)
B39: ⚠️ Notice: large standard errors relative to coefficients → individual predictors look unreliable, signs may even be counter-intuitive.
B41: 🔹 Step 3a — Standardise X: compute Z-scores Z = (x − μ) / σ
B42: Each predictor is rescaled to mean 0, std 1 so PCA isn't dominated by large-scale variables (Lot in thousands would otherwise drown out Garage in single digits).
B43: Stats | C43: Size | D43: Bedrooms | E43: Age | F43: Lot | G43: Garage
B44: Mean (μ) | C44: =AVERAGE(C10:C21) -> 2050 | D44: =AVERAGE(D10:D21) -> 3.3333333 | E44: =AVERAGE(E10:E21) -> 16.5 | F44: =AVERAGE(F10:F21) -> 6783.3333 | G44: =AVERAGE(G10:G21) -> 1.8333333
B45: Std Dev (σ) | C45: =_xlfn.STDEV.S(C10:C21) -> 576.03661 | D45: =_xlfn.STDEV.S(D10:D21) -> 0.88762536 | E45: =_xlfn.STDEV.S(E10:E21) -> 10.282377 | F45: =_xlfn.STDEV.S(F10:F21) -> 1838.8897 | G45: =_xlfn.STDEV.S(G10:G21) -> 0.71774056
B47: House | C47: Z(Size) | D47: Z(Bedrooms) | E47: Z(Age) | F47: Z(Lot) | G47: Z(Garage)
B48: =B10 -> 1 | C48: =(C10-C$44)/C$45 -> -0.95480042 | D48: =(D10-D$44)/D$45 -> -0.37553381 | E48: =(E10-E$44)/E$45 -> 0.34038823 | F48: =(F10-F$44)/F$45 -> -0.96978812 | G48: =(G10-G$44)/G$45 -> -1.1610509
...

Sheet Eigen Calc
B2: Eigendecomposition of the 5×5 correlation matrix R
B3: R = ZᵀZ / (n−1), where Z is the standardised data on '10. Case Study'!C48:G59 and n = 12.
B5: Correlation Matrix R (5×5) | O5: Eigenvalue Summary
C6: Size | D6: Bedrooms | E6: Age | F6: Lot | G6: Garage | O6: PC | P6: λ | Q6: % Var
B7: Size | C7: =SUMPRODUCT('10. Case Study'!$C$48:$C$59,'10. Case Study'!C$48:C$59)/11 -> 1 | D7: =SUMPRODUCT('10. Case Study'!$C$48:$C$59,'10. Case Study'!D$48:D$59)/11 -> 0.94233081 | E7: =SUMPRODUCT('10. Case Study'!$C$48:$C$59,'10. Case Study'!E$48:E$59)/11 -> -0.8963478 | F7: =SUMPRODUCT('10. Case Study'!$C$48:$C$59,'10. Case Study'!F$48:F$59)/11 -> 0.99725836 | G7: =SUMPRODUCT('10. Case Study'!$C$48:$C$59,'10. Case Study'!G$48:G$59)/11 -> 0.85753991 | O7: PC1 | P7: =H23 -> 4.6024843 | Q7: =P7/5 -> 0.92049685
B8: Bedrooms | C8: =SUMPRODUCT('10. Case Study'!$D$48:$D$59,'10. Case Study'!C$48:C$59)/11 -> 0.94233081 | D8: =SUMPRODUCT('10. Case Study'!$D$48:$D$59,'10. Case Study'!D$48:D$59)/11 -> 1 | E8: =SUMPRODUCT('10. Case Study'!$D$48:$D$59,'10. Case Study'!E$48:E$59)/11 -> -0.94625394 | F8: =SUMPRODUCT('10. Case Study'!$D$48:$D$59,'10. Case Study'!F$48:F$59)/11 -> 0.95054055 | G8: =SUMPRODUCT('10. Case Study'!$D$48:$D$59,'10. Case Study'!G$48:G$59)/11 -> 0.80860754 | O8: PC2 | P8: =H39 -> 0.22762534 | Q8: =P8/5 -> 0.045525068
B9: Age | C9: =SUMPRODUCT('10. Case Study'!$E$48:$E$59,'10. Case Study'!C$48:C$59)/11 -> -0.8963478 | D9: =SUMPRODUCT('10. Case Study'!$E$48:$E$59,'10. Case Study'!D$48:D$59)/11 -> -0.94625394 | E9: =SUMPRODUCT('10. Case Study'!$E$48:$E$59,'10. Case Study'!E$48:E$59)/11 -> 1 | F9: =SUMPRODUCT('10. Case Study'!$E$48:$E$59,'10. Case Study'!F$48:F$59)/11 -> -0.90677559 | G9: =SUMPRODUCT('10. Case Study'!$E$48:$E$59,'10. Case Study'!G$48:G$59)/11 -> -0.82531761 | O9: PC3 | P9: =H55 -> 0.13217855 | Q9: =P9/5 -> 0.026435709
B10: Lot | C10: =SUMPRODUCT('10. Case Study'!$F$48:$F$59,'10. Case Study'!C$48:C$59)/11 -> 0.99725836 | D10: =SUMPRODUCT('10. Case Study'!$F$48:$F$59,'10. Case Study'!D$48:D$59)/11 -> 0.95054055 | E10: =SUMPRODUCT('10. Case Study'!$F$48:$F$59,'10. Case Study'!E$48:E$59)/11 -> -0.90677559 | F10: =SUMPRODUCT('10. Case Study'!$F$48:$F$59,'10. Case Study'!F$48:F$59)/11 -> 1 | G10: =SUMPRODUCT('10. Case Study'!$F$48:$F$59,'10. Case Study'!G$48:G$59)/11 -> 0.8655741 | O10: PC4 | P10: =H71 -> 0.035463924 | Q10: =P10/5 -> 0.0070927847
B11: Garage | C11: =SUMPRODUCT('10. Case Study'!$G$48:$G$59,'10. Case Study'!C$48:C$59)/11 -> 0.85753991 | D11: =SUMPRODUCT('10. Case Study'!$G$48:$G$59,'10. Case Study'!D$48:D$59)/11 -> 0.80860754 | E11: =SUMPRODUCT('10. Case Study'!$G$48:$G$59,'10. Case Study'!E$48:E$59)/11 -> -0.82531761 | F11: =SUMPRODUCT('10. Case Study'!$G$48:$G$59,'10. Case Study'!F$48:F$59)/11 -> 0.8655741 | G11: =SUMPRODUCT('10. Case Study'!$G$48:$G$59,'10. Case Study'!G$48:G$59)/11 -> 1 | O11: PC5 | P11: =5-SUM(P7:P10) -> 0.0022479375 | Q11: =P11/5 -> 0.00044958749
O12: Sum | P12: =SUM(P7:P11) -> 5 | Q12: =SUM(Q7:Q11) -> 1
B13: PC1 — Power iteration on R (8 iterations)
B14: iter | C14: w1 | D14: w2 | E14: w3 | F14: w4 | G14: w5 | H14: λ = ||w|| | I14: v1 | J14: v2 | K14: v3 | L14: v4 | M14: v5
B15: 0 | I15: =1/SQRT(5) -> 0.4472136 | J15: =1/SQRT(5) -> 0.4472136 | K15: =1/SQRT(5) -> 0.4472136 | L15: =1/SQRT(5) -> 0.4472136 | M15: =1/SQRT(5) -> 0.4472136
B16: =B15+1 -> 1 | C16: =SUMPRODUCT($C$7:$G$7,$I15:$M15) -> 1.2972688 | D16: =SUMPRODUCT($C$8:$G$8,$I15:$M15) -> 1.2321741 | E16: =SUMPRODUCT($C$9:$G$9,$I15:$M15) -> -1.1514386 | F16: =SUMPRODUCT($C$10:$G$10,$I15:$M15) -> 1.2998699 | G16: =SUMPRODUCT($C$11:$G$11,$I15:$M15) -> 1.2103406 | H16: =SQRT(SUMSQ(C16:G16)) -> 2.7715621 | I16: =C16/$H16 -> 0.46806414 | J16: =D16/$H16 -> 0.44457747 | K16: =E16/$H16 -> -0.41544752 | L16: =F16/$H16 -> 0.46900262 | M16: =G16/$H16 -> 0.43669981
B17: =B16+1 -> 2 | C17: =SUMPRODUCT($C$7:$G$7,$I16:$M16) -> 2.101593 | D17: =SUMPRODUCT($C$8:$G$8,$I16:$M16) -> 2.0776924 | E17: =SUMPRODUCT($C$9:$G$9,$I16:$M16) -> -2.0413751 | F17: =SUMPRODUCT($C$10:$G$10,$I16:$M16) -> 2.1130861 | G17: =SUMPRODUCT($C$11:$G$11,$I16:$M16) -> 1.9464049 | H17: =SQRT(SUMSQ(C17:G17)) -> 4.5993843 | I17: =C17/$H17 -> 0.4569292 | J17: =D17/$H17 -> 0.45173272 | K17: =E17/$H17 -> -0.44383661 | L17: =F17/$H17 -> 0.45942804 | M17: =G17/$H17 -> 0.42318814
B18: =B17+1 -> 3 | C18: =SUMPRODUCT($C$7:$G$7,$I17:$M17) -> 2.101512 | D18: =SUMPRODUCT($C$8:$G$8,$I17:$M17) -> 2.0811914 | E18: =SUMPRODUCT($C$9:$G$9,$I17:$M17) -> -2.0467207 | F18: =SUMPRODUCT($C$10:$G$10,$I17:$M17) -> 2.1132557 | G18: =SUMPRODUCT($C$11:$G$11,$I17:$M17) -> 1.9442728 | H18: =SQRT(SUMSQ(C18:G18)) -> 4.60248 | I18: =C18/$H18 -> 0.45660426 | J18: =D18/$H18 -> 0.45218913 | K18: =E18/$H18 -> -0.44469953 | L18: =F18/$H18 -> 0.45915586 | M18: =G18/$H18 -> 0.42244025
B19: =B18+1 -> 4 | C19: =SUMPRODUCT($C$7:$G$7,$I18:$M18) -> 2.1014778 | D19: =SUMPRODUCT($C$8:$G$8,$I18:$M18) -> 2.0812947 | E19: =SUMPRODUCT($C$9:$G$9,$I18:$M18) -> -2.0468602 | F19: =SUMPRODUCT($C$10:$G$10,$I18:$M18) -> 2.1132284 | G19: =SUMPRODUCT($C$11:$G$11,$I18:$M18) -> 1.9440919 | H19: =SQRT(SUMSQ(C19:G19)) -> 4.6024842 | I19: =C19/$H19 -> 0.45659642 | J19: =D19/$H19 -> 0.45221115 | K19: =E19/$H19 -> -0.44472943 | L19: =F19/$H19 -> 0.45914951 | M19: =G19/$H19 -> 0.42240056
B20: =B19+1 -> 5 | C20: =SUMPRODUCT($C$7:$G$7,$I19:$M19) -> 2.1014772 | D20: =SUMPRODUCT($C$8:$G$8,$I19:$M19) -> 2.0812995 | E20: =SUMPRODUCT($C$9:$G$9,$I19:$M19) -> -2.0468654 | F20: =SUMPRODUCT($C$10:$G$10,$I19:$M19) -> 2.1132279 | G20: =SUMPRODUCT($C$11:$G$11,$I19:$M19) -> 1.9440825 | H20: =SQRT(SUMSQ(C20:G20)) -> 4.6024843 | I20: =C20/$H20 -> 0.45659628 | J20: =D20/$H20 -> 0.4522122 | K20: =E20/$H20 -> -0.44473056 | L20: =F20/$H20 -> 0.45914941 | M20: =G20/$H20 -> 0.42239852
B21: =B20+1 -> 6 | C21: =SUMPRODUCT($C$7:$G$7,$I20:$M20) -> 2.1014772 | D21: =SUMPRODUCT($C$8:$G$8,$I20:$M20) -> 2.0812997 | E21: =SUMPRODUCT($C$9:$G$9,$I20:$M20) -> -2.0468656 | F21: =SUMPRODUCT($C$10:$G$10,$I20:$M20) -> 2.1132279 | G21: =SUMPRODUCT($C$11:$G$11,$I20:$M20) -> 1.944082 | H21: =SQRT(SUMSQ(C21:G21)) -> 4.6024843 | I21: =C21/$H21 -> 0.45659628 | J21: =D21/$H21 -> 0.45221225 | K21: =E21/$H21 -> -0.44473061 | L21: =F21/$H21 -> 0.45914941 | M21: =G21/$H21 -> 0.42239841
B22: =B21+1 -> 7 | C22: =SUMPRODUCT($C$7:$G$7,$I21:$M21) -> 2.1014772 | D22: =SUMPRODUCT($C$8:$G$8,$I21:$M21) -> 2.0812998 | E22: =SUMPRODUCT($C$9:$G$9,$I21:$M21) -> -2.0468656 | F22: =SUMPRODUCT($C$10:$G$10,$I21:$M21) -> 2.1132279 | G22: =SUMPRODUCT($C$11:$G$11,$I21:$M21) -> 1.944082 | H22: =SQRT(SUMSQ(C22:G22)) -> 4.6024843 | I22: =C22/$H22 -> 0.45659628 | J22: =D22/$H22 -> 0.45221225 | K22: =E22/$H22 -> -0.44473061 | L22: =F22/$H22 -> 0.45914941 | M22: =G22/$H22 -> 0.42239841
B23: =B22+1 -> 8 | C23: =SUMPRODUCT($C$7:$G$7,$I22:$M22) -> 2.1014772 | D23: =SUMPRODUCT($C$8:$G$8,$I22:$M22) -> 2.0812998 | E23: =SUMPRODUCT($C$9:$G$9,$I22:$M22) -> -2.0468656 | F23: =SUMPRODUCT($C$10:$G$10,$I22:$M22) -> 2.1132279 | G23: =SUMPRODUCT($C$11:$G$11,$I22:$M22) -> 1.944082 | H23: =SQRT(SUMSQ(C23:G23)) -> 4.6024843 | I23: =C23/$H23 -> 0.45659628 | J23: =D23/$H23 -> 0.45221225 | K23: =E23/$H23 -> -0.44473061 | L23: =F23/$H23 -> 0.45914941 | M23: =G23/$H23 -> 0.42239841
B25: PC2 — Deflated matrix R₂ = R − λ₁v₁v₁ᵀ, then power iterate
C26: =C7-$H$23*$I$23*I$23 -> 0.040473316 | D26: =D7-$H$23*$I$23*J$23 -> -0.0079829275 | E26: =E7-$H$23*$I$23*K$23 -> 0.038243441 | F26: =F7-$H$23*$I$23*L$23 -> 0.032366335 | G26: =G7-$H$23*$I$23*M$23 -> -0.030120717
C27: =C8-$H$23*$J$23*I$23 -> -0.0079829275 | D27: =D8-$H$23*$J$23*J$23 -> 0.05881075 | E27: =E8-$H$23*$J$23*K$23 -> -0.020636226 | F27: =F8-$H$23*$J$23*L$23 -> -0.0050870111 | G27: =G8-$H$23*$J$23*M$23 -> -0.070530167
C28: =C9-$H$23*$K$23*I$23 -> 0.038243441 | D28: =D9-$H$23*$K$23*J$23 -> -0.020636226 | E28: =E9-$H$23*$K$23*K$23 -> 0.089696196 | F28: =F9-$H$23*$K$23*L$23 -> 0.033041562 | G28: =G9-$H$23*$K$23*M$23 -> 0.039275175
C29: =C10-$H$23*$L$23*I$23 -> 0.032366335 | D29: =D10-$H$23*$L$23*J$23 -> -0.0050870111 | E29: =E10-$H$23*$L$23*K$23 -> 0.033041562 | F29: =F10-$H$23*$L$23*L$23 -> 0.029712638 | G29: =G10-$H$23*$L$23*M$23 -> -0.02705002
C30: =C11-$H$23*$M$23*I$23 -> -0.030120717 | D30: =D11-$H$23*$M$23*J$23 -> -0.070530167 | E30: =E11-$H$23*$M$23*K$23 -> 0.039275175 | F30: =F11-$H$23*$M$23*L$23 -> -0.02705002 | G30: =G11-$H$23*$M$23*M$23 -> 0.17882285
B31: 0 | I31: =1/SQRT(5) -> 0.4472136 | J31: =-1/SQRT(5) -> -0.4472136 | K31: =1/SQRT(5) -> 0.4472136 | L31: =-1/SQRT(5) -> -0.4472136 | M31: =1/SQRT(5) -> 0.4472136
B32: =B31+1 -> 1 | C32: =SUMPRODUCT($C$26:$G$26,$I31:$M31) -> 0.010828219 | D32: =SUMPRODUCT($C$27:$G$27,$I31:$M31) -> -0.068366911 | E32: =SUMPRODUCT($C$28:$G$28,$I31:$M31) -> 0.069232903 | F32: =SUMPRODUCT($C$29:$G$29,$I31:$M31) -> 0.0061412489 | G32: =SUMPRODUCT($C$30:$G$30,$I31:$M31) -> 0.12770519 | H32: =SQRT(SUMSQ(C32:G32)) -> 0.16103047 | I32: =C32/$H32 -> 0.067243292 | J32: =D32/$H32 -> -0.42455886 | K32: =E32/$H32 -> 0.42993667 | L32: =F32/$H32 -> 0.038137187 | M32: =G32/$H32 -> 0.79304989
B33: =B32+1 -> 2 | C33: =SUMPRODUCT($C$26:$G$26,$I32:$M32) -> -9.9831096e-05 | D33: =SUMPRODUCT($C$27:$G$27,$I32:$M32) -> -0.090505639 | E33: =SUMPRODUCT($C$28:$G$28,$I32:$M32) -> 0.082303877 | F33: =SUMPRODUCT($C$29:$G$29,$I32:$M32) -> -0.0017769252 | G33: =SUMPRODUCT($C$30:$G$30,$I32:$M32) -> 0.18558846 | H33: =SQRT(SUMSQ(C33:G33)) -> 0.22228685 | I33: =C33/$H33 -> -0.00044910933 | J33: =D33/$H33 -> -0.40715697 | K33: =E33/$H33 -> 0.37025977 | L33: =F33/$H33 -> -0.0079938388 | M33: =G33/$H33 -> 0.83490526
B34: =B33+1 -> 3 | C34: =SUMPRODUCT($C$26:$G$26,$I33:$M33) -> -0.008014541 | D34: =SUMPRODUCT($C$27:$G$27,$I33:$M33) -> -0.090427729 | E34: =SUMPRODUCT($C$28:$G$28,$I33:$M33) -> 0.074122823 | F34: =SUMPRODUCT($C$29:$G$29,$I33:$M33) -> -0.0085310848 | G34: =SUMPRODUCT($C$30:$G$30,$I33:$M33) -> 0.19278876 | H34: =SQRT(SUMSQ(C34:G34)) -> 0.2257784 | I34: =C34/$H34 -> -0.035497377 | J34: =D34/$H34 -> -0.40051541 | K34: =E34/$H34 -> 0.328299 | L34: =F34/$H34 -> -0.037785212 | M34: =G34/$H34 -> 0.85388488
B35: =B34+1 -> 4 | C35: =SUMPRODUCT($C$26:$G$26,$I34:$M34) -> -0.012626722 | D35: =SUMPRODUCT($C$27:$G$27,$I34:$M34) -> -0.09007852 | E35: =SUMPRODUCT($C$28:$G$28,$I34:$M34) -> 0.068642752 | F35: =SUMPRODUCT($C$29:$G$29,$I34:$M34) -> -0.012484283 | G35: =SUMPRODUCT($C$30:$G$30,$I34:$M34) -> 0.19592784 | H35: =SQRT(SUMSQ(C35:G35)) -> 0.22699995 | I35: =C35/$H35 -> -0.055624336 | J35: =D35/$H35 -> -0.39682176 | K35: =E35/$H35 -> 0.30239104 | L35: =F35/$H35 -> -0.054996855 | M35: =G35/$H35 -> 0.86311843
B36: =B35+1 -> 5 | C36: =SUMPRODUCT($C$26:$G$26,$I35:$M35) -> -0.015296821 | D36: =SUMPRODUCT($C$27:$G$27,$I35:$M35) -> -0.089729668 | E36: =SUMPRODUCT($C$28:$G$28,$I35:$M35) -> 0.06526691 | F36: =SUMPRODUCT($C$29:$G$29,$I35:$M35) -> -0.014771719 | G36: =SUMPRODUCT($C$30:$G$30,$I35:$M35) -> 0.19737277 | H36: =SQRT(SUMSQ(C36:G36)) -> 0.22741898 | I36: =C36/$H36 -> -0.067262728 | J36: =D36/$H36 -> -0.39455664 | K36: =E36/$H36 -> 0.28698973 | L36: =F36/$H36 -> -0.064953768 | M36: =G36/$H36 -> 0.86788172
B37: =B36+1 -> 6 | C37: =SUMPRODUCT($C$26:$G$26,$I36:$M36) -> -0.016840689 | D37: =SUMPRODUCT($C$27:$G$27,$I36:$M36) -> -0.089471026 | E37: =SUMPRODUCT($C$28:$G$28,$I36:$M36) -> 0.063251722 | F37: =SUMPRODUCT($C$29:$G$29,$I36:$M36) -> -0.016093511 | G37: =SUMPRODUCT($C$30:$G$30,$I36:$M36) -> 0.1980798 | H37: =SQRT(SUMSQ(C37:G37)) -> 0.22756112 | I37: =C37/$H37 -> -0.074005126 | J37: =D37/$H37 -> -0.39317361 | K37: =E37/$H37 -> 0.27795487 | L37: =F37/$H37 -> -0.070721708 | M37: =G37/$H37 -> 0.8704466
B38: =B37+1 -> 7 | C38: =SUMPRODUCT($C$26:$G$26,$I37:$M37) -> -0.017734084 | D38: =SUMPRODUCT($C$27:$G$27,$I37:$M37) -> -0.089300979 | E38: =SUMPRODUCT($C$28:$G$28,$I37:$M37) -> 0.062065091 | F38: =SUMPRODUCT($C$29:$G$29,$I37:$M37) -> -0.01685806 | G38: =SUMPRODUCT($C$30:$G$30,$I37:$M37) -> 0.19844518 | H38: =SQRT(SUMSQ(C38:G38)) -> 0.22760914 | I38: =C38/$H38 -> -0.077914639 | J38: =D38/$H38 -> -0.39234355 | K38: =E38/$H38 -> 0.27268277 | L38: =F38/$H38 -> -0.074065828 | M38: =G38/$H38 -> 0.87186823
B39: =B38+1 -> 8 | C39: =SUMPRODUCT($C$26:$G$26,$I38:$M38) -> -0.018251622 | D39: =SUMPRODUCT($C$27:$G$27,$I38:$M38) -> -0.089195413 | E39: =SUMPRODUCT($C$28:$G$28,$I38:$M38) -> 0.061370901 | F39: =SUMPRODUCT($C$29:$G$29,$I38:$M38) -> -0.017300835 | G39: =SUMPRODUCT($C$30:$G$30,$I38:$M38) -> 0.19864201 | H39: =SQRT(SUMSQ(C39:G39)) -> 0.22762534 | I39: =C39/$H39 -> -0.080182732 | J39: =D39/$H39 -> -0.39185186 | K39: =E39/$H39 -> 0.26961366 | L39: =F39/$H39 -> -0.07600575 | M39: =G39/$H39 -> 0.87267087
B41: PC3 — Deflated matrix R₃ = R₂ − λ₂v₂v₂ᵀ, then power iterate
C42: =C26-$H$39*$I$39*I$39 -> 0.039009851 | D42: =D26-$H$39*$I$39*J$39 -> -0.015134859 | E42: =E26-$H$39*$I$39*K$39 -> 0.043164327 | F42: =F26-$H$39*$I$39*L$39 -> 0.030979107 | G42: =G26-$H$39*$I$39*M$39 -> -0.014193058
C43: =C27-$H$39*$J$39*I$39 -> -0.015134859 | D43: =D27-$H$39*$J$39*J$39 -> 0.023859362 | E43: =E27-$H$39*$J$39*K$39 -> 0.003412075 | F43: =F27-$H$39*$J$39*L$39 -> -0.011866375 | G43: =G27-$H$39*$J$39*M$39 -> 0.0073080723
C44: =C28-$H$39*$K$39*I$39 -> 0.043164327 | D44: =D28-$H$39*$K$39*J$39 -> 0.003412075 | E44: =E28-$H$39*$K$39*K$39 -> 0.073149763 | F44: =F28-$H$39*$K$39*L$39 -> 0.037706104 | G44: =G28-$H$39*$K$39*M$39 -> -0.014281422
...
